<?xml version="1.0" encoding="UTF-8"?>
<!-- Generated by org.testng.reporters.JUnitReportReporter -->
<testsuite hostname="PreetamHaste" failures="0" tests="3" name="testNgPractice.testNgPractice" time="0.011" errors="1" timestamp="2023-03-01T21:51:56 IST" skipped="1">
  <testcase classname="testNgPractice.testNgPractice" name="TestClass" time="0.011"/>
  <system-out/>
  <testcase classname="testNgPractice.testNgPractice" name="TestClass2" time="0.000">
    <error message="
Method testNgPractice.TestClass2()[pri:0, instance:testNgPractice.testNgPractice@932bc4a] should have thrown an exception of type class java.lang.ArithmeticException" type="org.testng.TestException">
      <![CDATA[org.testng.TestException: 
Method testNgPractice.TestClass2()[pri:0, instance:testNgPractice.testNgPractice@932bc4a] should have thrown an exception of type class java.lang.ArithmeticException
at org.testng.internal.invokers.ExpectedExceptionsHolder.noException(ExpectedExceptionsHolder.java:81)
at org.testng.internal.invokers.TestInvoker.considerExceptions(TestInvoker.java:873)
at org.testng.internal.invokers.TestInvoker.invokeMethod(TestInvoker.java:731)
at org.testng.internal.invokers.TestInvoker.invokeTestMethod(TestInvoker.java:221)
at org.testng.internal.invokers.MethodRunner.runInSequence(MethodRunner.java:50)
at org.testng.internal.invokers.TestInvoker$MethodInvocationAgent.invoke(TestInvoker.java:969)
at org.testng.internal.invokers.TestInvoker.invokeTestMethods(TestInvoker.java:194)
at org.testng.internal.invokers.TestMethodWorker.invokeTestMethods(TestMethodWorker.java:148)
at org.testng.internal.invokers.TestMethodWorker.run(TestMethodWorker.java:128)
at java.base/java.util.ArrayList.forEach(ArrayList.java:1511)
at org.testng.TestRunner.privateRun(TestRunner.java:829)
at org.testng.TestRunner.run(TestRunner.java:602)
at org.testng.SuiteRunner.runTest(SuiteRunner.java:437)
at org.testng.SuiteRunner.runSequentially(SuiteRunner.java:431)
at org.testng.SuiteRunner.privateRun(SuiteRunner.java:391)
at org.testng.SuiteRunner.run(SuiteRunner.java:330)
at org.testng.SuiteRunnerWorker.runSuite(SuiteRunnerWorker.java:52)
at org.testng.SuiteRunnerWorker.run(SuiteRunnerWorker.java:95)
at org.testng.TestNG.runSuitesSequentially(TestNG.java:1256)
at org.testng.TestNG.runSuitesLocally(TestNG.java:1176)
at org.testng.TestNG.runSuites(TestNG.java:1099)
at org.testng.TestNG.run(TestNG.java:1067)
at org.testng.remote.AbstractRemoteTestNG.run(AbstractRemoteTestNG.java:115)
at org.testng.remote.RemoteTestNG.initAndRun(RemoteTestNG.java:251)
at org.testng.remote.RemoteTestNG.main(RemoteTestNG.java:77)
]]>
    </error>
  </testcase> <!-- TestClass2 -->
  <system-out/>
  <testcase classname="testNgPractice.testNgPractice" name="TestClass1" time="0.000">
    <skipped/>
  </testcase> <!-- TestClass1 -->
  <system-out/>
</testsuite> <!-- testNgPractice.testNgPractice -->
